<!DOCTYPE html>
<html>
<head>
<meta charset="UTF-8">
<title>비동기작업</title>
</head>
<body>
<h1>Promise - 예외처리: Method Chaining II</h1>
<script>
const promise = new Promise((resolve, reject) => {
  // resolve();
  throw '오류 발생!!!';
})
.then(() => console.log("fulfilled! - 1"))
.then(() => console.log("fulfilled! - 2"))
.then(() => console.log("fulfilled! - 3"))
.then(() => console.log("fulfilled! - 4"))
.catch(() => console.log("catched!"));

// 오류가 발생하면,
// then()이 리턴한 promise를 계속 따라가면서 예외 핸들러를 찾아 호출한다.

console.log("끝!");

</script>
</body>
</html>